{"items": [{"title": "tensorflow: Changing n_classes to 2 yields &quot;ValueError: Shapes (?, 1) and (?,) are incompatible; &quot;", "is_answered": false, "view_count": 33, "question_id": 40314301, "last_activity_date": 1477936617, "link": "http://stackoverflow.com/questions/40314301/tensorflow-changing-n-classes-to-2-yields-valueerror-shapes-1-and-a", "owner": {"profile_image": "https://www.gravatar.com/avatar/3b3ee68be65ec221f29e534eea9514db?s=128&d=identicon&r=PG", "reputation": 1, "link": "http://stackoverflow.com/users/6534672/marie", "display_name": "Marie", "user_type": "registered", "user_id": 6534672}, "answer_count": 0, "last_edit_date": 1477936617, "score": 0, "tags": ["python", "machine-learning", "neural-network", "tensorflow", "python-3.4"], "creation_date": 1477695441}, {"owner": {"profile_image": "https://www.gravatar.com/avatar/44215d587ff1f8bc581d4098bfec2154?s=128&d=identicon&r=PG&f=1", "link": "http://stackoverflow.com/users/2089267/neove", "reputation": 941, "accept_rate": 84, "display_name": "NeoVe", "user_type": "registered", "user_id": 2089267}, "title": "TypeError(repr(o) + &quot; is not JSON serializable&quot;) - Odoo v8", "answer_count": 0, "view_count": 16, "last_activity_date": 1477936451, "question_id": 40347743, "score": 0, "tags": ["python", "json", "openerp", "odoo-8"], "link": "http://stackoverflow.com/questions/40347743/typeerrorrepro-is-not-json-serializable-odoo-v8", "creation_date": 1477936451, "is_answered": false}, {"owner": {"profile_image": "https://www.gravatar.com/avatar/dd6ab8a64810d8ca065dec125e80b96c?s=128&d=identicon&r=PG&f=1", "reputation": 1, "link": "http://stackoverflow.com/users/6744276/random-person-123", "display_name": "random_person_123", "user_type": "registered", "user_id": 6744276}, "title": "python 3.5 asyincio and aiohttp Errno 101 Network is unreachable", "answer_count": 0, "view_count": 7, "last_activity_date": 1477936378, "question_id": 40347726, "score": 0, "tags": ["python", "python-3.x", "python-asyncio", "aiohttp"], "link": "http://stackoverflow.com/questions/40347726/python-3-5-asyincio-and-aiohttp-errno-101-network-is-unreachable", "creation_date": 1477936378, "is_answered": false}, {"owner": {"profile_image": "https://www.gravatar.com/avatar/f485c69dfe40c241f3f53d63ea27aa1f?s=128&d=identicon&r=PG&f=1", "reputation": 1, "link": "http://stackoverflow.com/users/6135337/mfabi", "display_name": "mfabi", "user_type": "registered", "user_id": 6135337}, "title": "dataframe.describe() suppress scientific notation", "answer_count": 0, "view_count": 9, "last_activity_date": 1477936265, "question_id": 40347689, "score": 0, "tags": ["python", "pandas", "dataframe"], "link": "http://stackoverflow.com/questions/40347689/dataframe-describe-suppress-scientific-notation", "creation_date": 1477936265, "is_answered": false}, {"title": "Secure redirect - Capture source URL", "is_answered": false, "view_count": 19, "question_id": 37947274, "last_activity_date": 1477936215, "link": "http://stackoverflow.com/questions/37947274/secure-redirect-capture-source-url", "owner": {"profile_image": "https://i.stack.imgur.com/RsEMG.jpg?s=128&g=1", "reputation": 17, "link": "http://stackoverflow.com/users/3609139/nadav", "display_name": "Nadav", "user_type": "registered", "user_id": 3609139}, "answer_count": 0, "last_edit_date": 1477936215, "score": 0, "tags": ["python", "django", "security"], "creation_date": 1466519487}, {"owner": {"profile_image": "https://www.gravatar.com/avatar/1428b9f6e8be9c4f72fe895530ec12f2?s=128&d=identicon&r=PG&f=1", "link": "http://stackoverflow.com/users/3184332/hudsond7", "reputation": 166, "accept_rate": 92, "display_name": "hudsond7", "user_type": "registered", "user_id": 3184332}, "title": "Hadoop mapreduce task failing with 143", "answer_count": 0, "view_count": 10, "last_activity_date": 1477936029, "question_id": 40347638, "score": 1, "tags": ["python", "hadoop", "mapreduce"], "link": "http://stackoverflow.com/questions/40347638/hadoop-mapreduce-task-failing-with-143", "creation_date": 1477936029, "is_answered": false}, {"owner": {"profile_image": "https://lh3.googleusercontent.com/-5pMGlTk3zec/AAAAAAAAAAI/AAAAAAAAAqY/Ju3x45OEh8E/photo.jpg?sz=128", "reputation": 1, "link": "http://stackoverflow.com/users/7096396/nan", "display_name": "Nan", "user_type": "registered", "user_id": 7096396}, "title": "Python shell restarts when requests for a url by requests.post", "answer_count": 0, "view_count": 9, "last_activity_date": 1477935846, "question_id": 40347593, "score": -2, "tags": ["python", "python-2.7", "python-requests"], "link": "http://stackoverflow.com/questions/40347593/python-shell-restarts-when-requests-for-a-url-by-requests-post", "creation_date": 1477935846, "is_answered": false}, {"owner": {"profile_image": "https://lh3.googleusercontent.com/-1xM4lpW7iaU/AAAAAAAAAAI/AAAAAAAAAas/It2rP_VlfwA/photo.jpg?sz=128", "reputation": 4, "link": "http://stackoverflow.com/users/7071086/sankalp-raj", "display_name": "Sankalp Raj", "user_type": "registered", "user_id": 7071086}, "title": "P2P system always getting same getaddrinfo failed error 11001", "answer_count": 0, "view_count": 9, "last_activity_date": 1477935437, "question_id": 40347478, "score": 0, "tags": ["python", "p2p"], "link": "http://stackoverflow.com/questions/40347478/p2p-system-always-getting-same-getaddrinfo-failed-error-11001", "creation_date": 1477935437, "is_answered": false}, {"title": "Mutt in bash script raises an error in python (flask) application", "is_answered": false, "view_count": 24, "question_id": 40313035, "last_activity_date": 1477935362, "link": "http://stackoverflow.com/questions/40313035/mutt-in-bash-script-raises-an-error-in-python-flask-application", "owner": {"profile_image": "https://www.gravatar.com/avatar/11f0c28192994ae49cff70855340690f?s=128&d=identicon&r=PG&f=1", "reputation": 6, "link": "http://stackoverflow.com/users/6512252/godric", "display_name": "Godric", "user_type": "registered", "user_id": 6512252}, "answer_count": 0, "last_edit_date": 1477935362, "score": 0, "tags": ["python", "bash", "flask", "mutt"], "creation_date": 1477687870}, {"owner": {"profile_image": "https://www.gravatar.com/avatar/453dee1b3bacfbb401b476efdda71a34?s=128&d=identicon&r=PG&f=1", "link": "http://stackoverflow.com/users/5132509/regis-may", "reputation": 129, "accept_rate": 47, "display_name": "Regis May", "user_type": "registered", "user_id": 5132509}, "title": "Why does paramiko sporadically raise an exception?", "answer_count": 0, "view_count": 52, "last_activity_date": 1477935318, "question_id": 37556888, "score": 0, "tags": ["python", "ssh", "paramiko"], "link": "http://stackoverflow.com/questions/37556888/why-does-paramiko-sporadically-raise-an-exception", "creation_date": 1464734835, "is_answered": false}, {"title": "Performance characteristics of theano.shared variables vs numpy.ndarray (GPU)", "is_answered": false, "view_count": 16, "question_id": 40346697, "last_activity_date": 1477935291, "link": "http://stackoverflow.com/questions/40346697/performance-characteristics-of-theano-shared-variables-vs-numpy-ndarray-gpu", "owner": {"profile_image": "https://www.gravatar.com/avatar/f0a1f337a871aabf0ee7681a3fb21678?s=128&d=identicon&r=PG&f=1", "reputation": 50, "link": "http://stackoverflow.com/users/3747801/toke-faurby", "display_name": "Toke Faurby", "user_type": "registered", "user_id": 3747801}, "answer_count": 0, "last_edit_date": 1477935291, "score": 1, "tags": ["python", "numpy", "deep-learning", "theano-cuda"], "creation_date": 1477932389}, {"title": "Which Gobject Type for datetime and decimal in Python Gtk3", "is_answered": false, "view_count": 5, "question_id": 40347002, "last_activity_date": 1477935224, "link": "http://stackoverflow.com/questions/40347002/which-gobject-type-for-datetime-and-decimal-in-python-gtk3", "owner": {"profile_image": "https://www.gravatar.com/avatar/b223fe986d879dbc3b7262ec7f122fa5?s=128&d=identicon&r=PG", "link": "http://stackoverflow.com/users/1907997/oxidworks", "reputation": 110, "accept_rate": 58, "display_name": "oxidworks", "user_type": "registered", "user_id": 1907997}, "answer_count": 0, "last_edit_date": 1477935224, "score": 0, "tags": ["python", "gtk3", "gobject"], "creation_date": 1477933620}, {"owner": {"profile_image": "https://www.gravatar.com/avatar/74c18381bedfa71e903286af04b5edb9?s=128&d=identicon&r=PG&f=1", "reputation": 11, "link": "http://stackoverflow.com/users/6948460/user6948460", "display_name": "user6948460", "user_type": "registered", "user_id": 6948460}, "title": "Return PDF generated with FPDF in Flask on google app engine", "answer_count": 0, "view_count": 12, "last_activity_date": 1477935203, "question_id": 40347419, "score": 0, "tags": ["python", "google-app-engine", "pdf", "flask", "fpdf"], "link": "http://stackoverflow.com/questions/40347419/return-pdf-generated-with-fpdf-in-flask-on-google-app-engine", "creation_date": 1477935203, "is_answered": false}, {"owner": {"profile_image": "https://graph.facebook.com/906330676107472/picture?type=large", "reputation": 1, "link": "http://stackoverflow.com/users/5236121/anubhav-sharma", "display_name": "Anubhav Sharma", "user_type": "registered", "user_id": 5236121}, "title": "why is my code redirecting to another url?", "answer_count": 0, "view_count": 17, "last_activity_date": 1477934961, "question_id": 40347362, "score": 0, "tags": ["python", "web-scraping"], "link": "http://stackoverflow.com/questions/40347362/why-is-my-code-redirecting-to-another-url", "creation_date": 1477934961, "is_answered": false}, {"title": "python&#39;s urlparse.urljoin removes path when concatenating", "is_answered": false, "view_count": 14, "question_id": 40346986, "last_activity_date": 1477934842, "link": "http://stackoverflow.com/questions/40346986/pythons-urlparse-urljoin-removes-path-when-concatenating", "owner": {"profile_image": "https://i.stack.imgur.com/3eA8a.jpg?s=128&g=1", "link": "http://stackoverflow.com/users/2363252/chefarov", "reputation": 445, "accept_rate": 67, "display_name": "chefarov", "user_type": "registered", "user_id": 2363252}, "answer_count": 0, "last_edit_date": 1477934842, "score": 0, "tags": ["python", "python-2.x", "urlparse"], "creation_date": 1477933576}, {"owner": {"profile_image": "https://www.gravatar.com/avatar/235dcc1c473c4be1ddec787d32687650?s=128&d=identicon&r=PG", "link": "http://stackoverflow.com/users/3608005/moritz", "reputation": 1182, "accept_rate": 68, "display_name": "Moritz", "user_type": "registered", "user_id": 3608005}, "title": "kivy: plot and screen manager; plot not showing up", "answer_count": 0, "view_count": 17, "last_activity_date": 1477934691, "question_id": 40347303, "score": 0, "tags": ["python", "kivy"], "link": "http://stackoverflow.com/questions/40347303/kivy-plot-and-screen-manager-plot-not-showing-up", "creation_date": 1477934691, "is_answered": false}, {"title": "List of diverse lists to sorted pandas data frame", "is_answered": false, "view_count": 34, "question_id": 40346400, "last_activity_date": 1477934653, "link": "http://stackoverflow.com/questions/40346400/list-of-diverse-lists-to-sorted-pandas-data-frame", "owner": {"profile_image": "https://i.stack.imgur.com/a6Yzw.jpg?s=128&g=1", "link": "http://stackoverflow.com/users/6459589/spyth", "reputation": 76, "accept_rate": 0, "display_name": "SpyTh", "user_type": "registered", "user_id": 6459589}, "answer_count": 0, "last_edit_date": 1477934653, "score": -1, "tags": ["python", "pandas"], "creation_date": 1477931284}, {"title": "Query elements with association object with SQLAlchemy", "is_answered": false, "view_count": 15, "question_id": 40345319, "last_activity_date": 1477934563, "link": "http://stackoverflow.com/questions/40345319/query-elements-with-association-object-with-sqlalchemy", "owner": {"profile_image": "https://lh4.googleusercontent.com/-OZLeVXVweyE/AAAAAAAAAAI/AAAAAAAAAD8/yK9NkN_Rge0/photo.jpg?sz=128", "reputation": 1, "link": "http://stackoverflow.com/users/7095828/romain", "display_name": "Romain", "user_type": "registered", "user_id": 7095828}, "answer_count": 0, "last_edit_date": 1477934563, "score": 0, "tags": ["python", "sqlalchemy"], "creation_date": 1477927659}, {"owner": {"profile_image": "https://i.stack.imgur.com/fIRoA.jpg?s=128&g=1", "reputation": 127, "link": "http://stackoverflow.com/users/2134074/tol4trob", "display_name": "tol4trob", "user_type": "registered", "user_id": 2134074}, "title": "KeyError: None when invoking python nosetests", "answer_count": 0, "view_count": 6, "last_activity_date": 1477934454, "question_id": 40347232, "score": 0, "tags": ["python", "nose"], "link": "http://stackoverflow.com/questions/40347232/keyerror-none-when-invoking-python-nosetests", "creation_date": 1477934454, "is_answered": false}, {"owner": {"profile_image": "https://www.gravatar.com/avatar/281450ee5040ee1927d22f5adfc6ab6e?s=128&d=identicon&r=PG&f=1", "reputation": 30, "link": "http://stackoverflow.com/users/6452188/arturo", "display_name": "Arturo", "user_type": "registered", "user_id": 6452188}, "title": "how to make sure that a knob is added inside a panel?", "answer_count": 0, "view_count": 17, "last_activity_date": 1477934423, "question_id": 40347223, "score": 0, "tags": ["python", "nuke"], "link": "http://stackoverflow.com/questions/40347223/how-to-make-sure-that-a-knob-is-added-inside-a-panel", "creation_date": 1477934423, "is_answered": false}, {"title": "Google App Engine datastore POST not working", "is_answered": false, "view_count": 160, "question_id": 17774338, "last_activity_date": 1477934235, "link": "http://stackoverflow.com/questions/17774338/google-app-engine-datastore-post-not-working", "owner": {"profile_image": "https://www.gravatar.com/avatar/a342138bc2f44b7531e211298b44706e?s=128&d=identicon&r=PG", "link": "http://stackoverflow.com/users/2560541/user2560541", "reputation": 11, "accept_rate": 0, "display_name": "user2560541", "user_type": "registered", "user_id": 2560541}, "answer_count": 0, "last_edit_date": 1477934235, "score": 0, "tags": ["python", "google-app-engine", "post", "google-cloud-datastore"], "creation_date": 1374423532}, {"title": "I am getting the following exception using Pycharm?", "is_answered": false, "view_count": 14, "question_id": 40347037, "last_activity_date": 1477933990, "link": "http://stackoverflow.com/questions/40347037/i-am-getting-the-following-exception-using-pycharm", "owner": {"profile_image": "https://www.gravatar.com/avatar/a697526edb47067115f3467a11ab1121?s=128&d=identicon&r=PG&f=1", "link": "http://stackoverflow.com/users/2991331/slopeofhope", "reputation": 130, "accept_rate": 87, "display_name": "slopeofhope", "user_type": "registered", "user_id": 2991331}, "answer_count": 0, "last_edit_date": 1477933990, "score": -1, "tags": ["python", "pycharm", "mysql-python"], "creation_date": 1477933751}, {"owner": {"profile_image": "https://www.gravatar.com/avatar/24ac586dedae441c8d24e821d7d41677?s=128&d=identicon&r=PG", "link": "http://stackoverflow.com/users/1453722/zalavari", "reputation": 278, "accept_rate": 31, "display_name": "zalavari", "user_type": "registered", "user_id": 1453722}, "title": "Sync VideoCapture and Projection with opencv", "answer_count": 0, "view_count": 4, "last_activity_date": 1477933553, "question_id": 40346983, "score": 0, "tags": ["python", "opencv"], "link": "http://stackoverflow.com/questions/40346983/sync-videocapture-and-projection-with-opencv", "creation_date": 1477933553, "is_answered": false}, {"title": "Force Python to Use 4 digit Unicode Encoding (CSV Writer)", "is_answered": false, "view_count": 28, "question_id": 40346793, "last_activity_date": 1477933532, "link": "http://stackoverflow.com/questions/40346793/force-python-to-use-4-digit-unicode-encoding-csv-writer", "owner": {"profile_image": "https://www.gravatar.com/avatar/6397eaf15c7e845a26ffcf1722ea7813?s=128&d=identicon&r=PG", "link": "http://stackoverflow.com/users/667804/user667804", "reputation": 184, "accept_rate": 67, "display_name": "user667804", "user_type": "registered", "user_id": 667804}, "answer_count": 0, "last_edit_date": 1477933532, "score": 2, "tags": ["python", "csv", "unicode"], "creation_date": 1477932793}, {"owner": {"profile_image": "https://www.gravatar.com/avatar/9e5767dd9bb5ae54008b950cd10a5dbe?s=128&d=identicon&r=PG&f=1", "link": "http://stackoverflow.com/users/2422819/user2422819", "reputation": 54, "accept_rate": 50, "display_name": "user2422819", "user_type": "registered", "user_id": 2422819}, "title": "NetBeans Projects With Setup.Py Not Appearing", "answer_count": 0, "view_count": 7, "last_activity_date": 1477933073, "question_id": 40346862, "score": 0, "tags": ["python", "windows", "netbeans", "development-environment", "setuptools"], "link": "http://stackoverflow.com/questions/40346862/netbeans-projects-with-setup-py-not-appearing", "creation_date": 1477933073, "is_answered": false}, {"title": "Passing asyncio loop by argument or using default asyncio loop", "is_answered": false, "view_count": 33, "question_id": 40340493, "last_activity_date": 1477933020, "link": "http://stackoverflow.com/questions/40340493/passing-asyncio-loop-by-argument-or-using-default-asyncio-loop", "owner": {"profile_image": "https://i.stack.imgur.com/49k8V.jpg?s=128&g=1", "link": "http://stackoverflow.com/users/166605/g%c3%bcnther-jena", "reputation": 1204, "accept_rate": 100, "display_name": "G&#252;nther Jena", "user_type": "registered", "user_id": 166605}, "answer_count": 0, "last_edit_date": 1477933020, "score": 3, "tags": ["python", "python-3.5", "python-asyncio"], "creation_date": 1477910284}, {"owner": {"profile_image": "https://www.gravatar.com/avatar/6c813075893457d03c7c2969c3cb0b6b?s=128&d=identicon&r=PG&f=1", "reputation": 20, "link": "http://stackoverflow.com/users/6446006/fattel", "display_name": "fattel", "user_type": "registered", "user_id": 6446006}, "title": "&quot;grouped/clustered&quot; regions in vector in R/python", "answer_count": 0, "view_count": 26, "last_activity_date": 1477932748, "question_id": 40343813, "score": 1, "tags": ["python", "r"], "link": "http://stackoverflow.com/questions/40343813/grouped-clustered-regions-in-vector-in-r-python", "creation_date": 1477922726, "is_answered": false}, {"title": "TypeError: coercing to Unicode: need string or buffer, list found", "is_answered": false, "view_count": 20, "question_id": 40346659, "last_activity_date": 1477932588, "link": "http://stackoverflow.com/questions/40346659/typeerror-coercing-to-unicode-need-string-or-buffer-list-found", "owner": {"profile_image": "https://lh4.googleusercontent.com/--MLMrqF1j0I/AAAAAAAAAAI/AAAAAAAAAB4/BTBvQQxLO0c/photo.jpg?sz=128", "reputation": 1, "link": "http://stackoverflow.com/users/7096194/aj-wagner", "display_name": "aj wagner", "user_type": "registered", "user_id": 7096194}, "answer_count": 0, "last_edit_date": 1477932588, "score": -5, "tags": ["python"], "creation_date": 1477932204}, {"title": "scipy.optimize.root, success = True, but not finding reasonable solution", "is_answered": false, "view_count": 19, "question_id": 40345754, "last_activity_date": 1477932231, "link": "http://stackoverflow.com/questions/40345754/scipy-optimize-root-success-true-but-not-finding-reasonable-solution", "owner": {"profile_image": "https://www.gravatar.com/avatar/a6d9adbc6223791973c9da64f0cb1a8b?s=128&d=identicon&r=PG&f=1", "reputation": 38, "link": "http://stackoverflow.com/users/6345518/scotty1", "display_name": "Scotty1-", "user_type": "registered", "user_id": 6345518}, "answer_count": 0, "last_edit_date": 1477932231, "score": 0, "tags": ["python", "scipy"], "creation_date": 1477928937}, {"title": "XCode 8: Loading a plug-in failed", "is_answered": false, "view_count": 415, "question_id": 39062263, "last_activity_date": 1477931900, "link": "http://stackoverflow.com/questions/39062263/xcode-8-loading-a-plug-in-failed", "owner": {"profile_image": "https://i.stack.imgur.com/fxCKU.png?s=128&g=1", "reputation": 16, "link": "http://stackoverflow.com/users/3601059/gparmeggiani", "display_name": "GParmeggiani", "user_type": "registered", "user_id": 3601059}, "answer_count": 0, "last_edit_date": 1471770026, "score": 3, "tags": ["python", "ios", "xcode"], "creation_date": 1471767714}], "has_more": true, "quota_max": 10000, "quota_remaining": 8855}